Traceback (most recent call last):
  File "/home/runner/.cache/pypoetry/virtualenvs/sdsprog2-rJz_c7Cc-py3.11/lib/python3.11/site-packages/jupyter_cache/executors/utils.py", line 58, in single_nb_execution
    executenb(
  File "/home/runner/.cache/pypoetry/virtualenvs/sdsprog2-rJz_c7Cc-py3.11/lib/python3.11/site-packages/nbclient/client.py", line 1305, in execute
    return NotebookClient(nb=nb, resources=resources, km=km, **kwargs).execute()
           ^^^^^^^^^^^^^^^^^^^^^^^^^^^^^^^^^^^^^^^^^^^^^^^^^^^^^^^^^^^^^^^^^^^^^
  File "/home/runner/.cache/pypoetry/virtualenvs/sdsprog2-rJz_c7Cc-py3.11/lib/python3.11/site-packages/jupyter_core/utils/__init__.py", line 165, in wrapped
    return loop.run_until_complete(inner)
           ^^^^^^^^^^^^^^^^^^^^^^^^^^^^^^
  File "/opt/hostedtoolcache/Python/3.11.9/x64/lib/python3.11/asyncio/base_events.py", line 654, in run_until_complete
    return future.result()
           ^^^^^^^^^^^^^^^
  File "/home/runner/.cache/pypoetry/virtualenvs/sdsprog2-rJz_c7Cc-py3.11/lib/python3.11/site-packages/nbclient/client.py", line 705, in async_execute
    await self.async_execute_cell(
  File "/home/runner/.cache/pypoetry/virtualenvs/sdsprog2-rJz_c7Cc-py3.11/lib/python3.11/site-packages/nbclient/client.py", line 1058, in async_execute_cell
    await self._check_raise_for_error(cell, cell_index, exec_reply)
  File "/home/runner/.cache/pypoetry/virtualenvs/sdsprog2-rJz_c7Cc-py3.11/lib/python3.11/site-packages/nbclient/client.py", line 914, in _check_raise_for_error
    raise CellExecutionError.from_cell_and_msg(cell, exec_reply_content)
nbclient.exceptions.CellExecutionError: An error occurred while executing the following cell:
------------------
initial_state = "q0"
accept_state = {}

automata = automathon.DFA(q, sigma, delta, initial_state, accept_state)
automata.view(file_name="dfa")

g = graphviz.Source.from_file("dfa.gv")
g.render(format="svg")
with open("dfa.gv.svg", "rb") as f:
    svg = SVG(f.read())

glue("auto01", svg)
------------------


[0;31m---------------------------------------------------------------------------[0m
[0;31mFileNotFoundError[0m                         Traceback (most recent call last)
File [0;32m~/.cache/pypoetry/virtualenvs/sdsprog2-rJz_c7Cc-py3.11/lib/python3.11/site-packages/graphviz/backend.py:164[0m, in [0;36mrun[0;34m(cmd, input, capture_output, check, encoding, quiet, **kwargs)[0m
[1;32m    163[0m [38;5;28;01mtry[39;00m:
[0;32m--> 164[0m     proc [38;5;241m=[39m [43msubprocess[49m[38;5;241;43m.[39;49m[43mPopen[49m[43m([49m[43mcmd[49m[43m,[49m[43m [49m[43mstartupinfo[49m[38;5;241;43m=[39;49m[43mget_startupinfo[49m[43m([49m[43m)[49m[43m,[49m[43m [49m[38;5;241;43m*[39;49m[38;5;241;43m*[39;49m[43mkwargs[49m[43m)[49m
[1;32m    165[0m [38;5;28;01mexcept[39;00m [38;5;167;01mOSError[39;00m [38;5;28;01mas[39;00m e:

File [0;32m/opt/hostedtoolcache/Python/3.11.9/x64/lib/python3.11/subprocess.py:1026[0m, in [0;36mPopen.__init__[0;34m(self, args, bufsize, executable, stdin, stdout, stderr, preexec_fn, close_fds, shell, cwd, env, universal_newlines, startupinfo, creationflags, restore_signals, start_new_session, pass_fds, user, group, extra_groups, encoding, errors, text, umask, pipesize, process_group)[0m
[1;32m   1023[0m             [38;5;28mself[39m[38;5;241m.[39mstderr [38;5;241m=[39m io[38;5;241m.[39mTextIOWrapper([38;5;28mself[39m[38;5;241m.[39mstderr,
[1;32m   1024[0m                     encoding[38;5;241m=[39mencoding, errors[38;5;241m=[39merrors)
[0;32m-> 1026[0m     [38;5;28;43mself[39;49m[38;5;241;43m.[39;49m[43m_execute_child[49m[43m([49m[43margs[49m[43m,[49m[43m [49m[43mexecutable[49m[43m,[49m[43m [49m[43mpreexec_fn[49m[43m,[49m[43m [49m[43mclose_fds[49m[43m,[49m
[1;32m   1027[0m [43m                        [49m[43mpass_fds[49m[43m,[49m[43m [49m[43mcwd[49m[43m,[49m[43m [49m[43menv[49m[43m,[49m
[1;32m   1028[0m [43m                        [49m[43mstartupinfo[49m[43m,[49m[43m [49m[43mcreationflags[49m[43m,[49m[43m [49m[43mshell[49m[43m,[49m
[1;32m   1029[0m [43m                        [49m[43mp2cread[49m[43m,[49m[43m [49m[43mp2cwrite[49m[43m,[49m
[1;32m   1030[0m [43m                        [49m[43mc2pread[49m[43m,[49m[43m [49m[43mc2pwrite[49m[43m,[49m
[1;32m   1031[0m [43m                        [49m[43merrread[49m[43m,[49m[43m [49m[43merrwrite[49m[43m,[49m
[1;32m   1032[0m [43m                        [49m[43mrestore_signals[49m[43m,[49m
[1;32m   1033[0m [43m                        [49m[43mgid[49m[43m,[49m[43m [49m[43mgids[49m[43m,[49m[43m [49m[43muid[49m[43m,[49m[43m [49m[43mumask[49m[43m,[49m
[1;32m   1034[0m [43m                        [49m[43mstart_new_session[49m[43m,[49m[43m [49m[43mprocess_group[49m[43m)[49m
[1;32m   1035[0m [38;5;28;01mexcept[39;00m:
[1;32m   1036[0m     [38;5;66;03m# Cleanup if the child failed starting.[39;00m

File [0;32m/opt/hostedtoolcache/Python/3.11.9/x64/lib/python3.11/subprocess.py:1955[0m, in [0;36mPopen._execute_child[0;34m(self, args, executable, preexec_fn, close_fds, pass_fds, cwd, env, startupinfo, creationflags, shell, p2cread, p2cwrite, c2pread, c2pwrite, errread, errwrite, restore_signals, gid, gids, uid, umask, start_new_session, process_group)[0m
[1;32m   1954[0m [38;5;28;01mif[39;00m err_filename [38;5;129;01mis[39;00m [38;5;129;01mnot[39;00m [38;5;28;01mNone[39;00m:
[0;32m-> 1955[0m     [38;5;28;01mraise[39;00m child_exception_type(errno_num, err_msg, err_filename)
[1;32m   1956[0m [38;5;28;01melse[39;00m:

[0;31mFileNotFoundError[0m: [Errno 2] No such file or directory: 'dot'

During handling of the above exception, another exception occurred:

[0;31mExecutableNotFound[0m                        Traceback (most recent call last)
Cell [0;32mIn[29], line 5[0m
[1;32m      2[0m accept_state [38;5;241m=[39m {}
[1;32m      4[0m automata [38;5;241m=[39m automathon[38;5;241m.[39mDFA(q, sigma, delta, initial_state, accept_state)
[0;32m----> 5[0m [43mautomata[49m[38;5;241;43m.[39;49m[43mview[49m[43m([49m[43mfile_name[49m[38;5;241;43m=[39;49m[38;5;124;43m"[39;49m[38;5;124;43mdfa[39;49m[38;5;124;43m"[39;49m[43m)[49m
[1;32m      7[0m g [38;5;241m=[39m graphviz[38;5;241m.[39mSource[38;5;241m.[39mfrom_file([38;5;124m"[39m[38;5;124mdfa.gv[39m[38;5;124m"[39m)
[1;32m      8[0m g[38;5;241m.[39mrender([38;5;28mformat[39m[38;5;241m=[39m[38;5;124m"[39m[38;5;124msvg[39m[38;5;124m"[39m)

File [0;32m~/.cache/pypoetry/virtualenvs/sdsprog2-rJz_c7Cc-py3.11/lib/python3.11/site-packages/automathon/finiteAutomata/dfa.py:382[0m, in [0;36mDFA.view[0;34m(self, file_name, node_attr, edge_attr)[0m
[1;32m    379[0m     [38;5;28;01mfor[39;00m s [38;5;129;01min[39;00m [38;5;28mself[39m[38;5;241m.[39mdelta[q]:
[1;32m    380[0m         dot[38;5;241m.[39medge(q, [38;5;28mself[39m[38;5;241m.[39mdelta[q][s], label[38;5;241m=[39ms)
[0;32m--> 382[0m [43mdot[49m[38;5;241;43m.[39;49m[43mrender[49m[43m([49m[43m)[49m

File [0;32m~/.cache/pypoetry/virtualenvs/sdsprog2-rJz_c7Cc-py3.11/lib/python3.11/site-packages/graphviz/files.py:243[0m, in [0;36mFile.render[0;34m(self, filename, directory, view, cleanup, format, renderer, formatter, quiet, quiet_view)[0m
[1;32m    240[0m [38;5;28;01mif[39;00m [38;5;28mformat[39m [38;5;129;01mis[39;00m [38;5;28;01mNone[39;00m:
[1;32m    241[0m     [38;5;28mformat[39m [38;5;241m=[39m [38;5;28mself[39m[38;5;241m.[39m_format
[0;32m--> 243[0m rendered [38;5;241m=[39m [43mbackend[49m[38;5;241;43m.[39;49m[43mrender[49m[43m([49m[38;5;28;43mself[39;49m[38;5;241;43m.[39;49m[43m_engine[49m[43m,[49m[43m [49m[38;5;28;43mformat[39;49m[43m,[49m[43m [49m[43mfilepath[49m[43m,[49m
[1;32m    244[0m [43m                          [49m[43mrenderer[49m[38;5;241;43m=[39;49m[43mrenderer[49m[43m,[49m[43m [49m[43mformatter[49m[38;5;241;43m=[39;49m[43mformatter[49m[43m,[49m
[1;32m    245[0m [43m                          [49m[43mquiet[49m[38;5;241;43m=[39;49m[43mquiet[49m[43m)[49m
[1;32m    247[0m [38;5;28;01mif[39;00m cleanup:
[1;32m    248[0m     log[38;5;241m.[39mdebug([38;5;124m'[39m[38;5;124mdelete [39m[38;5;132;01m%r[39;00m[38;5;124m'[39m, filepath)

File [0;32m~/.cache/pypoetry/virtualenvs/sdsprog2-rJz_c7Cc-py3.11/lib/python3.11/site-packages/graphviz/backend.py:223[0m, in [0;36mrender[0;34m(***failed resolving arguments***)[0m
[1;32m    220[0m [38;5;28;01melse[39;00m:
[1;32m    221[0m     cwd [38;5;241m=[39m [38;5;28;01mNone[39;00m
[0;32m--> 223[0m [43mrun[49m[43m([49m[43mcmd[49m[43m,[49m[43m [49m[43mcapture_output[49m[38;5;241;43m=[39;49m[38;5;28;43;01mTrue[39;49;00m[43m,[49m[43m [49m[43mcwd[49m[38;5;241;43m=[39;49m[43mcwd[49m[43m,[49m[43m [49m[43mcheck[49m[38;5;241;43m=[39;49m[38;5;28;43;01mTrue[39;49;00m[43m,[49m[43m [49m[43mquiet[49m[38;5;241;43m=[39;49m[43mquiet[49m[43m)[49m
[1;32m    224[0m [38;5;28;01mreturn[39;00m rendered

File [0;32m~/.cache/pypoetry/virtualenvs/sdsprog2-rJz_c7Cc-py3.11/lib/python3.11/site-packages/graphviz/backend.py:167[0m, in [0;36mrun[0;34m(cmd, input, capture_output, check, encoding, quiet, **kwargs)[0m
[1;32m    165[0m [38;5;28;01mexcept[39;00m [38;5;167;01mOSError[39;00m [38;5;28;01mas[39;00m e:
[1;32m    166[0m     [38;5;28;01mif[39;00m e[38;5;241m.[39merrno [38;5;241m==[39m errno[38;5;241m.[39mENOENT:
[0;32m--> 167[0m         [38;5;28;01mraise[39;00m ExecutableNotFound(cmd)
[1;32m    168[0m     [38;5;28;01melse[39;00m:
[1;32m    169[0m         [38;5;28;01mraise[39;00m

[0;31mExecutableNotFound[0m: failed to execute ['dot', '-Kdot', '-Tpng', '-O', 'dfa.gv'], make sure the Graphviz executables are on your systems' PATH

